Workbook

Sheet 30 Case Audit
A1: ID | B1: Original validator category | C1: Drug | D1: Extracted disease / target | E1: Manual review status | F1: Gemma extraction error | G1: Validator false negative | H1: Manual disposition | I1: Evidence rationale | J1: Sources discussed / reviewed | K1: External evidence conclusion | L1: Failure / review mechanism | M1: Exact URL | N1: Audit compilation date
A2: 1 | B2: UNRESOLVED | C2: Amikacin | D2: bone and joint infections | E2: TRUE INDICATION / REGULATORY_SEMANTIC_SUPPORT | F2: NO | G2: YES | H2: validator false negative | I2: DailyMed wording describes infections of bones and joints | J2: DrugBank; DailyMed | K2: DailyMed support identified | L2: Word-order / phrasing | M2: https://dailymed.nlm.nih.gov/dailymed/drugInfo.cfm?setid=0b56f6df-a05d-4520-8bf0-d7cefe20f6ad | N2: 2026-10-01 (compilation; not source access date)
A3: 2 | B3: UNRESOLVED | C3: Riociguat | D3: idiopathic/heritable pulmonary artery hypertension | E3: TRUE INDICATION / SUPPORTED_BUT_QUALIFIED | F3: NO | G3: YES | H3: Supported with qualifier | I3: PAH (WHO Group 1) label; idiopathic/heritable subgroups in supporting clinical description | J3: DrugBank; DailyMed | K3: DailyMed indication for PAH | L3: Abbreviation / qualifier | M3: https://dailymed.nlm.nih.gov/dailymed/drugInfo.cfm?setid=8092c64b-e240-43c3-9d2e-e0dd7708d96f | N3: 2026-10-01 (compilation; not source access date)
A4: 3 | B4: UNRESOLVED | C4: Tyrosine | D4: depression | E4: EXTERNAL_REGULATORY_UNCONFIRMED | F4: Unknown | G4: Unknown | H4: Keep in review | I4: Source mentions antidepressant activity with uncertain evidence; no official indication established | J4: DrugBank; regulatory label search | K4: No suitable regulatory confirmation established | L4: Uncertain evidence context | M4: Not preserved in available review notes | N4: 2026-10-01 (compilation; not source access date)
A5: 4 | B5: UNRESOLVED | C5: Ampicillin | D5: GI infection | E5: SUPPORTED_SEMANTIC_EQUIVALENT | F5: NO | G5: YES | H5: validator false negative | I5: DailyMed uses Gastrointestinal Infections | J5: DrugBank; DailyMed | K5: DailyMed support identified | L5: Abbreviation / morphology | M5: https://dailymed.nlm.nih.gov/dailymed/drugInfo.cfm?setid=302e6df7-37c5-4625-8a61-3e2f302addf2 | N5: 2026-10-01 (compilation; not source access date)
A6: 5 | B6: UNRESOLVED | C6: Fluoxetine | D6: predmenstrual dysphoric disorder | E6: SOURCE_SUPPORTED_EXTRACTION / EXTERNAL_REGULATORY_UNCONFIRMED | F6: small spelling mistake | G6: NO | H6: Keep in review | I6: Source refers to premenstrual dysphoric disorder; extraction has typo; checked label did not list PMDD | J6: DrugBank; DrugCentral; DailyMed | K6: Regulatory support not established in checked label, Drugcentral : Premenstrual dysphoric disorder | L6: Typo / source discordance | M6: https://drugcentral.org/drugcard/1209?q=Fluoxetine | N6: 2026-10-01 (compilation; not source access date)
A7: 6 | B7: UNSUPPORTED_TEXT_GROUNDED | C7: Phenelzine | D7: bipolar disorder | E7: NOT_SUPPORTED_AS_INDICATION | F7: YES | G7: NO | H7: Extraction error | I7: Mention is contextual/comorbidity; label concerns depression | J7: DrugBank; DailyMed | K7: No bipolar indication in checked label | L7: Clinical context | M7: Not preserved in available review notes | N7: 2026-10-01 (compilation; not source access date)
A8: 7 | B8: UNSUPPORTED_TEXT_GROUNDED | C8: Echothiophate | D8: subacute or chronic angle-closure glaucoma | E8: SOURCE_DISCORDANCE_EXTERNAL_UNCONFIRMED | F8: NO | G8: NO | H8: Keep in review | I8: DrugBank supports conditional use after iridectomy or when surgery unavailable; checked label describes other indications | J8: DrugBank; DailyMed (PHOSPHOLINE IODIDE) | K8: Specific external confirmation not established | L8: Source/label discordance | M8: https://dailymed.nlm.nih.gov/dailymed/drugInfo.cfm?setid=8afc8951-db76-4f27-8752-7c0d6aa47244 | N8: 2026-10-01 (compilation; not source access date)
A9: 8 | B9: UNSUPPORTED_TEXT_GROUNDED | C9: Rivaroxaban | D9: venous thromboembolic events | E9: SUPPORTED_SEMANTIC_EQUIVALENT | F9: NO | G9: YES | H9: validator false negative | I9: DailyMed describes venous thromboembolism (VTE), drug central describes as Venous thromboembolic disease | J9: DrugBank; DailyMed; Drugcentral | K9: DailyMed equivalent terminology identified | L9: Terminology / synonym | M9: https://dailymed.nlm.nih.gov/dailymed/drugInfo.cfm?setid=c0efa9f9-ca7a-471a-8030-99056fa5da09 | N9: 2026-10-01 (compilation; not source access date)
A10: 9 | B10: UNSUPPORTED_TEXT_GROUNDED | C10: Vandetanib | D10: congenital long QT syndrome | E10: CONTRAINDICATION_NOT_INDICATION | F10: YES | G10: NO | H10: Extraction error | I10: Mention occurs in contraindication context; label indication is medullary thyroid cancer | J10: DrugBank; DailyMed | K10: Not an indication | L10: Contraindication | M10: https://dailymed.nlm.nih.gov/dailymed/drugInfo.cfm?setid=e5721cb8-4185-47b9-bbb3-1c587e558a03 | N10: 2026-10-01 (compilation; not source access date)
A11: 10 | B11: UNSUPPORTED_TEXT_GROUNDED | C11: Gemcitabine | D11: transitional cell carcinoma of bladder | E11: SOURCE_DISCORDANCE_EXTERNAL_UNCONFIRMED | F11: NO | G11: NO | H11: Keep in review | I11: DrugBank mentions advanced/metastatic bladder TCC with cisplatin; checked label did not list bladder indication | J11: DrugBank; DailyMed;DrugCentral | K11: Not established in checked label | L11: Source/label discordance | M11: https://drugcentral.org/drugcard/1283?q=Gemcitabine ; https://dailymed.nlm.nih.gov/dailymed/drugInfo.cfm?setid=a5949d02-29eb-4626-ad35-b7614bb0fa95 | N11: 2026-10-01 (compilation; not source access date)
A12: 11 | B12: UNSUPPORTED_TEXT_GROUNDED | C12: Prasugrel | D12: atherothrombotic events | E12: SUPPORTED_SEMANTIC_EQUIVALENT | F12: NO | G12: YES | H12: validator false negative | I12: Label describes reduction of thrombotic cardiovascular events in ACS/PCI population | J12: DrugBank; DailyMed; UMLS | K12: Equivalent indication context found | L12: Terminology / qualifier | M12: https://dailymed.nlm.nih.gov/dailymed/drugInfo.cfm?setid=8b67ca60-d7e4-4c04-bbc6-dae86a7c7675 | N12: 2026-10-01 (compilation; not source access date)
A13: 12 | B13: UNSUPPORTED_TEXT_GROUNDED | C13: Metronidazole | D13: Helicobacter pylori infection | E13: OFF_LABEL_USE_NOT_APPROVED_INDICATION | F13: YES | G13: NO | H13: Do not auto-approve as labelled indication | I13: DrugBank explicitly identifies off-label use; combination product does not prove monotherapy indication | J13: DrugBank; DailyMed; UMLS | K13: Monotherapy approval not established | L13: Off-label / formulation | M13: Not preserved in available review notes | N13: 2026-10-01 (compilation; not source access date)
... A31: 30 | B31: NON_THERAPEUTIC_INDICATION_REVIEW | C31: Iopromide | D31: imaging-related target | E31: CORRECT_NON_THERAPEUTIC | F31: YES | G31: NO | H31: Safety gate appropriate | I31: ULTRAVIST iodinated contrast for imaging/CT lesion evaluation | J31: DrugBank; DailyMed (ULTRAVIST) | K31: Regulatory diagnostic role identified | L31: Contrast imaging | M31: https://dailymed.nlm.nih.gov/dailymed/drugInfo.cfm?setid=65647318-27e4-4f37-bd68-50eea52d6c5b | N31: 2026-10-01 (compilation; not source access date)

Sheet 20 Confirmed Sample
A1: ID | B1: Relation ID | C1: Original validator category | D1: Drug | E1: Extracted disease / target | F1: UMLS concept | G1: Pipeline evidence sources | H1: Pipeline regulatory URL | I1: Manual judgement | J1: Gemma extraction error | K1: Validator false positive | L1: Evidence rationale | M1: Failure / review mechanism | N1: Review date
A2: 1 | B2: 1017 | C2: CONFIRMED_DRUGCENTRAL_CUI_AND_REGULATORY | D2: Belimumab | E2: systemic lupus erythematosus | F2: C0024141 | G2: DrugCentral; DailyMed; FDA/openFDA | H2: https://dailymed.nlm.nih.gov/dailymed/drugInfo.cfm?setid=2fa3c528-1777-4628-8a55-a69dae2381a3 , https://drugcentral.org/drugcard/4949?q=Belimumab , https://api.fda.gov/drug/label.json?search=openfda.generic_name:belimumab&limit=10 | I2: CORRECT | J2: NO | K2: NO | L2: The Belimumab-systemic lupus erythematosus relation was confirmed through manual review. DrugCentral lists systemic lupus erythematosus as an indication for belimumab, and both DailyMed and openFDA confirm its use for treating active systemic lupus erythematosus. UMLS also identifies the disease under CUI C0024141. The evidence supports the extracted relation, and the validator's confirmation was correct. | M2: NO | N2: 46319
A3: 2 | B3: 695 | C3: CONFIRMED_REGULATORY | D3: Doxepin | E3: organic disease | F3: C0683324 | G3: DailyMed; FDA/openFDA | H3: https://dailymed.nlm.nih.gov/dailymed/drugInfo.cfm?setid=e6a4cb10-1928-4abe-8797-404c9ddc37dd&utm_source=chatgpt.com | I3: incorrect | J3: YES | K3: YES | L3: DailyMed mentions organic disease in the Indications and Usage section, but only in relation to depression or anxiety associated with an underlying organic disease. Doxepin is used to treat depression or anxiety, not the organic disease itself. The extracted relation therefore misinterprets the clinical context and should not have been automatically confirmed. | M3: YES
A4: 3 | B4: 599 | C4: CONFIRMED_DRUGCENTRAL_CUI_DISAMBIGUATED_AND_REGULATORY | D4: Burosumab | E4: X-linked hypophosphatemia | F4: – | G4: DailyMed;DrugCentral | H4: https://dailymed.nlm.nih.gov/dailymed/drugInfo.cfm?setid=102f96a0-6e3a-4fc1-b204-34d604683af6 , https://drugcentral.org/drugcard/5282?q=Burosumab | I4: CORRECT | J4: NO | K4: NO | L4: DailyMed confirms that burosumab (Crysvita) is indicated for treating X-linked hypophosphatemia. DrugCentral also lists the condition under the related name familial X-linked hypophosphatemic rickets, and UMLS supports the disease terminology. The extracted relation is correct and agrees with the available regulatory and structured evidence. | M4: no
A5: 4 | B5: 924 | C5: CONFIRMED_REGULATORY | D5: Tobramycin | E5: intra-abdominal infections | F5: C1112209 | G5: DailyMed | H5: https://dailymed.nlm.nih.gov/dailymed/drugInfo.cfm?setid=a9897444-71f6-42af-9b71-4aa77829ade0 | I5: CORRECT | J5: NO | K5: NO | L5: Tobramycin->intra-abdominal infections was supported by the DailyMed prescribing information, which lists intra-abdominal infections among the indications for tobramycin injection. This supports the extracted drug-disease relationship and the validator's automatic confirmation. | M5: no
A6: 5 | B6: 662 | C6: CONFIRMED_REGULATORY | D6: Misoprostol | E6: osteoarthritis | F6: C0029408 | G6: DrugCentral | H6: https://drugcentral.org/drugcard/1817?q=Misoprostol | I6: CORRECT | J6: NO | K6: NO | L6: Drug central says it has indication for "Osteoarthritis in Patients at High Ulcer Risk" | M6: no
A7: 6 | B7: 424 | C7: CONFIRMED_DRUGCENTRAL_CUI_DISAMBIGUATED_AND_REGULATORY | D7: Semaglutide | E7: obesity | F7: – | G7: DrugCentral; | H7: https://drugcentral.org/drugcard/5267?q=Semaglutide | I7: CORRECT | J7: NO | K7: NO | L7: DrugCentral lists obesity as an indication for semaglutide. This is consistent with the therapeutic use of semaglutide for weight management in patients with obesity. The extracted relation is supported by DrugCentral and appears to have been correctly confirmed by the validator. | M7: no
A8: 7 | B8: 899 | C8: CONFIRMED_DRUGCENTRAL_CUI | D8: Guanidine | E8: Eaton-Lambert syndrome | F8: C0022972 | G8: DrugCentral | H8: https://drugcentral.org/drugcard/1344?q=Guanidine | I8: CORRECT | J8: NO | K8: NO | L8: DrugCentral lists Eaton-Lambert syndrome as an indication for guanidine, matching the extracted drug-disease relation. This provides structured evidence supporting the validator's confirmation.
A9: 8 | B9: 1067 | C9: CONFIRMED_REGULATORY | D9: Ritlecitinib | E9: severe alopecia areata | F9: – | G9: DailyMed; DrugCentral | H9: https://dailymed.nlm.nih.gov/dailymed/drugInfo.cfm?setid=6b2f9446-fb23-4741-b73a-5a2f993733c3 , https://drugcentral.org/drugcard/5728?q=Ritlecitinib | I9: CORRECT | J9: NO | K9: NO | L9: DrugCentral and DailyMed both confirm that ritlecitinib (Litfulo) is indicated for the treatment of severe alopecia areata. The extracted relation matches the reported therapeutic indication, supporting the validator's automatic confirmation.
A10: 9 | B10: 884 | C10: CONFIRMED_REGULATORY | D10: Doxycycline | E10: malaria | F10: C0024530 | G10: FDA/openFDA | H10: https://api.fda.gov/drug/label.json?search=openfda.generic_name:doxycycline&limit=10 | I10: CORRECT | J10: NO | K10: NO | L10: The openFDA prescribing information confirms that doxycycline is indicated for malaria prophylaxis in travellers to areas with resistant Plasmodium falciparum. This supports the extracted malaria association as a preventive indication rather than direct treatment.
A11: 10 | B11: 1908 | C11: CONFIRMED_DRUGCENTRAL_CUI | D11: Dexpanthenol | E11: paralytic ileus | F11: C0030446 | G11: DrugCentral | H11: https://drugcentral.org/drugcard/838?q=Dexpanthenol | I11: CORRECT | J11: NO | K11: NO | L11: DrugCentral lists paralytic ileus as an indication for dexpanthenol, matching the extracted drug-disease relation. This supports the validator's confirmation. | M11: no
A12: 11 | B12: 1020 | C12: CONFIRMED_REGULATORY | D12: Linagliptin | E12: type 1 diabetes | F12: C0011854 | G12: DailyMed; FDA/openFDA | H12: https://dailymed.nlm.nih.gov/dailymed/drugInfo.cfm?setid=c797ea5c-cab7-494b-9044-27eba0cfe40f , https://drugcentral.org/drugcard/4175?q=Linagliptin , https://api.fda.gov/drug/label.json?search=openfda.brand_name:TRADJENTA&limit=5 | I12: INCORRECT | J12: YES | K12: YES | L12: Incorrect indication. DailyMed identifies linagliptin (TRADJENTA) as a treatment for type 2 diabetes mellitus and explicitly states that it is not recommended for patients with type 1 diabetes because it would not be effective. DrugCentral also lists type 2 diabetes as the indication, with no corresponding type 1 indication. The extracted relation is therefore a false positive, likely arising from failure to distinguish disease subtypes or interpret the negative statement in the regulatory label.
A13: 12 | B13: 1434 | C13: CONFIRMED_REGULATORY | D13: Prednisolone phosphate | E13: hematologic disorders | F13: C0018939 | G13: DailyMed | H13: https://dailymed.nlm.nih.gov/dailymed/drugInfo.cfm?setid=ebbc1751-9381-4db1-89ff-ae5a2963fb2c | I13: CORRECT | J13: NO | K13: NO | L13: DailyMed confirms that prednisolone phosphate is indicated for several hematologic disorders, including autoimmune hemolytic anemia, thrombocytopenia, and pure red cell aplasia. These conditions support the extracted broader indication of hematologic disorders. The relation is therefore considered correct.
A14: 13 | B14: 239 | C14: CONFIRMED_REGULATORY | D14: Methylprednisolone | E14: endocrine disorders | F14: C0014130 | G14: DailyMed; | H14: https://dailymed.nlm.nih.gov/dailymed/drugInfo.cfm?setid=738753c7-507d-4881-5194-02dd7597768b | I14: CORRECT | J14: NO | K14: NO | L14: DailyMed lists endocrine disorders under the approved indications for methylprednisolone sodium succinate, including adrenal insufficiency, congenital adrenal hyperplasia, and thyroiditis. This supports the extracted relation, although the indication applies to specific endocrine conditions rather than all endocrine disorders.
A15: 14 | B15: 531 | C15: CONFIRMED_DRUGCENTRAL_CUI | D15: Captopril | E15: essential hypertension | F15: C0085580 | G15: DrugCentral;DailyMed | H15: https://dailymed.nlm.nih.gov/dailymed/drugInfo.cfm?setid=5b44ab6e-6cd9-4e12-b9be-d2e4d954acb5 , https://drugcentral.org/drugcard/484?q=Captopril | I15: CORRECT | J15: NO | K15: NO | L15: DailyMed confirms that captopril is indicated for the treatment of hypertension, while DrugCentral lists hypertensive disorder as an indication. These findings support the extracted relation with essential hypertension, although the sources use broader terminology.
A16: 15 | B16: 842 | C16: CONFIRMED_REGULATORY | D16: Cyanocobalamin | E16: gluten enteropathy | F16: – | G16: DailyMed | H16: https://dailymed.nlm.nih.gov/dailymed/drugInfo.cfm?setid=cd8d188a-fa5d-4580-bcb1-ac8617118cbb | I16: CORRECT- partially as it is indirect relation | J16: NO | K16: NO | L16: DailyMed mentions gluten enteropathy under Indications and Usage, but cyanocobalamin is indicated for vitamin B12 deficiency resulting from malabsorption associated with this condition. It does not treat gluten enteropathy directly, so the extracted relationship is only indirectly supported (partially correct as it is indirect relation).
A17: 16 | B17: 875 | C17: CONFIRMED_DRUGCENTRAL_CUI_DISAMBIGUATED_AND_REGULATORY | D17: Doxycycline | E17: inclusion conjunctivitis | F17: – | G17: DailyMed; | H17: https://dailymed.nlm.nih.gov/dailymed/drugInfo.cfm?setid=ddd9a47e-7d7c-4d0c-aaa6-32702570f696 | I17: CORRECT | J17: NO | K17: NO | L17: The DailyMed label explicitly lists this condition under Indications and Usage as an approved treatment indication for doxycycline. This supports the extracted drug-disease relationship.
A18: 17 | B18: 1566 | C18: CONFIRMED_DRUGCENTRAL_CUI_DISAMBIGUATED_AND_REGULATORY | D18: Imipramine | E18: depression | F18: – | G18: DrugCentral; DailyMed; | H18: https://dailymed.nlm.nih.gov/dailymed/drugInfo.cfm?setid=92ca69d4-cdba-4789-91a9-922664d52498 , https://drugcentral.org/drugcard/1427?q=Imipramine | I18: CORRECT | J18: NO | K18: NO | L18: Both DrugCentral and DailyMed support this indication for imipramine. DrugCentral lists the condition as an indication, and the DailyMed label confirms its use under Indications and Usage.
A19: 18 | B19: 679 | C19: CONFIRMED_REGULATORY | D19: Sertraline | E19: major depressive disorder | F19: C1269683 | G19: DailyMed; DrugCentral | H19: https://dailymed.nlm.nih.gov/dailymed/drugInfo.cfm?setid=a5c49e6e-b8e0-4a75-99e6-b88e323ce653 , https://drugcentral.org/drugcard/2436?q=Sertraline | I19: CORRECT | J19: NO | K19: NO | L19: DrugCentral lists this condition as an indication for sertraline, and the DailyMed label also confirms its use under Indications and Usage. Both sources support the extracted drug–disease relationship.
A20: 19 | B20: 2110 | C20: CONFIRMED_REGULATORY | D20: Sevabertinib | E20: HER2 (ERBB2) tyrosine kinase domain (TKD) activating mutations | F20: – | G20: DailyMed | H20: https://dailymed.nlm.nih.gov/dailymed/drugInfo.cfm?setid=d7a11334-6e7a-445b-9a16-bdcd9acbe61f | I20: CORRECT | J20: NO | K20: NO | L20: DailyMed confirms sevabertinib as a treatment for locally advanced or metastatic non-squamous non-small cell lung cancer in adults whose tumors have HER2 activating mutations. The indication is approved under accelerated approval. This supports the extracted relationship, provided the specific cancer subtype and mutation requirements are retained.
A21: 20 | B21: 1460 | C21: CONFIRMED_DRUGCENTRAL_CUI_AND_REGULATORY | D21: Alteplase | E21: acute myocardial infarction | F21: C0155626 | G21: DrugCentral; DailyMed | H21: https://dailymed.nlm.nih.gov/dailymed/drugInfo.cfm?setid=c669f77c-fa48-478b-a14b-80b20a0139c2 , https://drugcentral.org/drugcard/5141?q=Alteplase | I21: CORRECT | J21: NO | K21: NO | L21: Confirmed by both DrugCentral and DailyMed. Alteplase is indicated for acute myocardial infarction, acute ischemic stroke, and acute massive pulmonary embolism. All three relationships are supported by DrugCentral, while DailyMed provides explicit regulatory evidence under the Indications and Usage section. The specific clinical qualifiers should be preserved.

Sheet Audit Summary
A1: Audit category | B1: Reviewed cases | C1: Total pipeline category
A2: UNRESOLVED | B2: 5 | C2: 24
A3: UNSUPPORTED_TEXT_GROUNDED | B3: 20 | C3: 964
A4: NON_THERAPEUTIC_INDICATION_REVIEW | B4: 5 | C4: 48
A5: TOTAL | B5: 30 | C5: 1036
A7: Study metric | B7: Value
A8: DrugBank records | B8: 500
A9: Candidate relations | B9: 2110
A10: Automatically confirmed | B10: 1074
A11: Routed to review | B11: 1036
A12: Manual audit sample | B12: 30
A14: Interpretation | B14: Important qualification
A15: Sampling | B15: Purposefully selected cases; not representative of all review-routed relations
A16: Manual statuses | B16: Qualitative adjudications, not machine-generated final pipeline statuses
A17: Source verification | B17: URLs and retrieval timestamps not retained in available review summary; blank/unverified fields must not be interpreted as independent source archive
A19: Confirmed-sample check (random) | B19: Value | C19: How computed
A20: Sample | B20: =COUNTA('20 Confirmed Sample'!B2:B21) -> 20 | C20: Random 20 of 1,074 automatically confirmed relations (pandas sample, random_state = 42)
A21: Judged | B21: =COUNTA('20 Confirmed Sample'!I2:I21) -> 20
A22: CORRECT | B22: =COUNTIF('20 Confirmed Sample'!I2:I21,"CORRECT") -> 17
A23: INCORRECT | B23: =COUNTIF('20 Confirmed Sample'!I2:I21,"INCORRECT") -> 2
A24: UNSURE | B24: =COUNTIF('20 Confirmed Sample'!I2:I21,"UNSURE") -> 0
A25: Precision (CORRECT / judged) | B25: =IF(B21=0,"",B22/B21) -> 0.85 | C25: UNSURE counted as not correct (conservative)
A26: 95% CI lower (Wilson) | B26: =IF(B21=0,"",(B25+1.96^2/(2*B21)-1.96*SQRT(B25*(1-B25)/B21+1.96^2/(4*B21^2)))/(1+1.96^2/B21)) -> 0.6395767 | C26: z = 1.96
A27: 95% CI upper (Wilson) | B27: =IF(B21=0,"",(B25+1.96^2/(2*B21)+1.96*SQRT(B25*(1-B25)/B21+1.96^2/(4*B21^2)))/(1+1.96^2/B21)) -> 0.94763221
A30: Review-routed audit (purposive, 30 cases) | B30: Value | C30: How computed
A31: Cases reviewed | B31: =COUNTA('30 Case Audit'!A2:A31) -> 30 | C31: 20 UNSUPPORTED_TEXT_GROUNDED, 5 UNRESOLVED, 5 NON_THERAPEUTIC (purposive)
A32: Gemma extraction error = YES | B32: =COUNTIF('30 Case Audit'!F2:F31,"YES") -> 17 | C32: Column F
A33: Gemma extraction error = NO | B33: =COUNTIF('30 Case Audit'!F2:F31,"NO") -> 11
A34: Gemma extraction error = other / uncertain | B34: =B31-B32-B33 -> 2 | C34: Any value other than YES/NO (e.g. Unknown)
A35: Validator false negative = YES | B35: =COUNTIF('30 Case Audit'!G2:G31,"YES") -> 7 | C35: Column G: valid relation the validator missed
A36: Validator false negative = NO | B36: =COUNTIF('30 Case Audit'!G2:G31,"NO") -> 22
A37: Validator false negative = other / uncertain | B37: =B31-B35-B36 -> 1
A39: By validator category | B39: Reviewed | C39: Extraction error = YES | D39: Validator false negative = YES | E39: Neither (kept in review / uncertain)
A40: UNRESOLVED | B40: =COUNTIF('30 Case Audit'!B2:B31,A40) -> 5 | C40: =COUNTIFS('30 Case Audit'!B2:B31,A40,'30 Case Audit'!F2:F31,"YES") -> 0 | D40: =COUNTIFS('30 Case Audit'!B2:B31,A40,'30 Case Audit'!G2:G31,"YES") -> 3 | E40: =B40-C40-D40 -> 2
A41: UNSUPPORTED_TEXT_GROUNDED | B41: =COUNTIF('30 Case Audit'!B2:B31,A41) -> 20 | C41: =COUNTIFS('30 Case Audit'!B2:B31,A41,'30 Case Audit'!F2:F31,"YES") -> 12 | D41: =COUNTIFS('30 Case Audit'!B2:B31,A41,'30 Case Audit'!G2:G31,"YES") -> 4 | E41: =B41-C41-D41 -> 4
A42: NON_THERAPEUTIC_INDICATION_REVIEW | B42: =COUNTIF('30 Case Audit'!B2:B31,A42) -> 5 | C42: =COUNTIFS('30 Case Audit'!B2:B31,A42,'30 Case Audit'!F2:F31,"YES") -> 5 | D42: =COUNTIFS('30 Case Audit'!B2:B31,A42,'30 Case Audit'!G2:G31,"YES") -> 0 | E42: =B42-C42-D42 -> 0
A43: TOTAL | B43: =SUM(B40:B42) -> 30 | C43: =SUM(C40:C42) -> 17 | D43: =SUM(D40:D42) -> 7 | E43: =SUM(E40:E42) -> 6
A45: Manual disposition | B45: Cases | C45: % of audited cases
A46: Extraction error | B46: =COUNTIF('30 Case Audit'!H2:H31,"Extraction error") -> 8 | C46: =IF($B$31=0,"",B46/$B$31) -> 0.26666667
A47: Validator false negative | B47: =COUNTIF('30 Case Audit'!H2:H31,"validator false negative") -> 5 | C47: =IF($B$31=0,"",B47/$B$31) -> 0.16666667
...

Sheet Method and Source Notes
A1: Field | B1: Definition / use
A2: Scope | B2: 30 purposively selected relations: 20 unsupported, 5 unresolved, 5 non-therapeutic.
A3: Review basis | B3: Reconstructed from the prior case-by-case review recorded in this project; NOT a fresh external verification.
A4: Original validator category | B4: Status assigned by the automated pipeline prior to human review.
A5: Manual review status | B5: Qualitative decision after examining DrugBank indication text and available external evidence.
A6: Manual disposition | B6: Interpretation for audit; does not rewrite the original pipeline CSV.
A7: Evidence rationale | B7: Brief reason for the manual adjudication.
A8: Sources discussed / reviewed | B8: Source names previously discussed; does not imply all sources were successfully retrieved for each row.
A9: External evidence conclusion | B9: Distinguishes regulatory confirmation, source-only support, and incomplete checks.
A10: Exact URL | B10: No exact URLs were preserved in the accessible review summary; field is explicitly unverified.
A11: Review date | B11: Individual source access dates not available. Compilation date is NOT review/access date.
A12: Evidence hierarchy | B12: DailyMed / FDA labels primary for regulatory claims; DrugBank for extraction context; UMLS for concept identity; PubChem/Mayo supporting only.
... A19: Data licence | B19: The DrugBank indication text column is for private checking only; remove it before sharing or depositing this workbook.
